<?xml version="1.0" encoding="UTF-8"?>
<testsuite errors="1" failures="0" file="validate_colors_list_tests.py" name="validate_colors_list_tests.TestValidateColorsList-20191013144919" skipped="0" tests="3" time="0.004" timestamp="2019-10-13T14:49:19">
	<testcase classname="validate_colors_list_tests.TestValidateColorsList" file="src/unittest/python/validate_colors_list_tests.py" line="9" name="test4ColorsBands" time="0.000" timestamp="2019-10-13T14:49:19">
		<system-out>
<![CDATA[]]>		</system-out>
		<system-err>
<![CDATA[]]>		</system-err>
	</testcase>
	<testcase classname="validate_colors_list_tests.TestValidateColorsList" file="src/unittest/python/validate_colors_list_tests.py" line="13" name="test5ColorBands" time="0.000" timestamp="2019-10-13T14:49:19">
		<system-out>
<![CDATA[]]>		</system-out>
		<system-err>
<![CDATA[]]>		</system-err>
	</testcase>
	<testcase classname="validate_colors_list_tests.TestValidateColorsList" file="src/unittest/python/validate_colors_list_tests.py" line="19" name="test3ColorBands" time="0.004" timestamp="2019-10-13T14:49:19">
		<error message="'_AssertRaisesContext' object has no attribute 'Exception'" type="AttributeError">
<![CDATA[Traceback (most recent call last):
  File "/home/student/Desktop/SystemProgramming/Projects/NolanWilliamsProject2/src/unittest/python/validate_colors_list_tests.py", line 23, in test3ColorBands
    self.assertTrue("There should only be 4 or 5 bands" in error.Exception)
AttributeError: '_AssertRaisesContext' object has no attribute 'Exception'
]]>		</error>
		<system-out>
<![CDATA[]]>		</system-out>
		<system-err>
<![CDATA[]]>		</system-err>
	</testcase>
</testsuite>
