<?xml version="1.0" encoding="UTF-8"?>
<testsuite errors="0" failures="1" file="decode_resistance_tests.py" name="decode_resistance_tests.TestDecodeResistance-20191013171619" skipped="0" tests="1" time="0.000" timestamp="2019-10-13T17:16:19">
	<testcase classname="decode_resistance_tests.TestDecodeResistance" file="src/unittest/python/decode_resistance_tests.py" line="9" name="testDecodeReistanceLowMultiplerAndTolerance4Band" time="0.000" timestamp="2019-10-13T17:16:19">
		<failure message="'12' != 12" type="AssertionError">
<![CDATA[Traceback (most recent call last):
  File "/home/student/Desktop/SystemProgramming/Projects/NolanWilliamsProject2/src/unittest/python/decode_resistance_tests.py", line 11, in testDecodeReistanceLowMultiplerAndTolerance4Band
    self.assertEquals("12", expected['value'])
AssertionError: '12' != 12
]]>		</failure>
		<system-out>
<![CDATA[]]>		</system-out>
		<system-err>
<![CDATA[]]>		</system-err>
	</testcase>
</testsuite>
