<?xml version="1.0" encoding="UTF-8"?>
<testsuite errors="0" failures="1" file="validate_colors_list_tests.py" name="validate_colors_list_tests.TestValidateColorsList-20191012192256" skipped="0" tests="2" time="0.004" timestamp="2019-10-12T19:22:56">
	<testcase classname="validate_colors_list_tests.TestValidateColorsList" file="src/unittest/python/validate_colors_list_tests.py" line="7" name="testValidColors4Bands" time="0.000" timestamp="2019-10-12T19:22:56">
		<system-out>
<![CDATA[]]>		</system-out>
		<system-err>
<![CDATA[]]>		</system-err>
	</testcase>
	<testcase classname="validate_colors_list_tests.TestValidateColorsList" file="src/unittest/python/validate_colors_list_tests.py" line="12" name="testInvalidNumberOf3Bands" time="0.004" timestamp="2019-10-12T19:22:56">
		<failure message="ValueError not raised" type="AssertionError">
<![CDATA[Traceback (most recent call last):
  File "/home/student/Desktop/SystemProgramming/Projects/NolanWilliamsProject2/src/unittest/python/validate_colors_list_tests.py", line 15, in testInvalidNumberOf3Bands
    validateColorsList(listOfColors)
AssertionError: ValueError not raised
]]>		</failure>
		<system-out>
<![CDATA[]]>		</system-out>
		<system-err>
<![CDATA[]]>		</system-err>
	</testcase>
</testsuite>
